<?xml version="1.0" ?>
<!-- =================================================================================== -->
<!-- |    This document was autogenerated by xacro from auto_pro1_with_laser.xacro     | -->
<!-- |    EDITING THIS FILE BY HAND IS NOT RECOMMENDED                                 | -->
<!-- =================================================================================== -->
<robot name="auto_pro1" xmlns:xacro="http://ros.org/wiki/xacro">
  <!-- Put all the color definitions in a separate file -->
  <material name="Black">
    <color rgba="0.2 0.2 0.2 1.0"/>
  </material>
  <material name="TransparentBlack">
    <color rgba="0.2 0.2 0.2 0.8"/>
  </material>
  <material name="Orange">
    <color rgba="1.0  0.55 0.0 1.0"/>
  </material>
  <material name="Grey">
    <color rgba="0.7 0.7 0.7 1.0"/>
  </material>
  <material name="DarkGrey">
    <color rgba="0.3 0.3 0.3 1.0"/>
  </material>
  <material name="Red">
    <color rgba="0.8 0.0 0.0 1.0"/>
  </material>
  <material name="White">
    <color rgba="1.0 1.0 1.0 1.0"/>
  </material>
  <material name="OffWhite">
    <color rgba="0.8 0.8 0.8 1.0"/>
  </material>
  <material name="Blue">
    <color rgba="0.0 0.0 0.8 1.0"/>
  </material>
  <material name="Green">
    <color rgba="0.0 0.8 0.0 1.0"/>
  </material>
  <material name="TransparentGreen">
    <color rgba="0.0 0.8 0.0 0.5"/>
  </material>
  <material name="Goldenrod">
    <color rgba="1.0 0.75 0.145 1.0"/>
    <!--255 193 37 -->
  </material>
  <link name="base_footprint">
    <visual>
      <origin rpy="0 0 0" xyz="0 0 0"/>
      <geometry>
        <box size="0.05 0.05 0.001"/>
      </geometry>
      <material name="TransparentGreen"/>
    </visual>
  </link>
  <joint name="base_joint" type="fixed">
    <origin rpy="0 0 0" xyz="0 0 0.2"/>
    <!--${wheel_radius + wheel_offset_z}-->
    <parent link="base_footprint"/>
    <child link="base_link"/>
  </joint>
  <joint name="base_l1_wheel_joint" type="continuous">
    <origin rpy="1.57075 0 0 " xyz="0.228 0.2675 -0.065"/>
    <axis xyz="0 0 1"/>
    <limit effort="100" velocity="100"/>
    <safety_controller k_velocity="10"/>
    <parent link="base_link"/>
    <child link="base_l1_wheel_link"/>
  </joint>
  <link name="base_l1_wheel_link">
    <visual>
      <origin rpy="0 0 0" xyz="0 0 0"/>
      <geometry>
        <cylinder length="0.08" radius="0.135"/>
      </geometry>
      <material name="Black"/>
    </visual>
  </link>
  <joint name="base_l2_wheel_joint" type="continuous">
    <origin rpy="1.57075 0 0 " xyz="-0.228 0.2675 -0.065"/>
    <axis xyz="0 0 1"/>
    <limit effort="100" velocity="100"/>
    <safety_controller k_velocity="10"/>
    <parent link="base_link"/>
    <child link="base_l2_wheel_link"/>
  </joint>
  <link name="base_l2_wheel_link">
    <visual>
      <origin rpy="0 0 0" xyz="0 0 0"/>
      <geometry>
        <cylinder length="0.08" radius="0.135"/>
      </geometry>
      <material name="Black"/>
    </visual>
  </link>
  <joint name="base_r1_wheel_joint" type="continuous">
    <origin rpy="-1.57075 0 0 " xyz="0.228 -0.2675 -0.065"/>
    <axis xyz="0 0 1"/>
    <limit effort="100" velocity="100"/>
    <safety_controller k_velocity="10"/>
    <parent link="base_link"/>
    <child link="base_r1_wheel_link"/>
  </joint>
  <link name="base_r1_wheel_link">
    <visual>
      <origin rpy="0 0 0" xyz="0 0 0"/>
      <geometry>
        <cylinder length="0.08" radius="0.135"/>
      </geometry>
      <material name="Black"/>
    </visual>
  </link>
  <joint name="base_r2_wheel_joint" type="continuous">
    <origin rpy="-1.57075 0 0 " xyz="-0.228 -0.2675 -0.065"/>
    <axis xyz="0 0 1"/>
    <limit effort="100" velocity="100"/>
    <safety_controller k_velocity="10"/>
    <parent link="base_link"/>
    <child link="base_r2_wheel_link"/>
  </joint>
  <link name="base_r2_wheel_link">
    <visual>
      <origin rpy="0 0 0" xyz="0 0 0"/>
      <geometry>
        <cylinder length="0.08" radius="0.135"/>
      </geometry>
      <material name="Black"/>
    </visual>
  </link>
  <!-- A box-and-cylinder model of the Hokuyo URG-04LX-UG01 laser scanner -->
  <link name="base_link">
    <visual>
      <origin rpy="0 0 0" xyz="0 0 0"/>
      <geometry>
        <box size="0.726 0.425 0.2"/>
      </geometry>
      <material name="Goldenrod"/>
    </visual>
    <collision>
      <origin rpy="0 0 0" xyz="0 0 0"/>
      <geometry>
        <box size="0.726 0.615 0.2"/>
      </geometry>
    </collision>
  </link>
  <joint name="base_laser_bottom_joint" type="fixed">
    <origin rpy="0 0 0 " xyz="0.1 0.0 0.1"/>
    <parent link="base_link"/>
    <child link="base_laser_bottom"/>
  </joint>
  <link name="base_laser_bottom">
    <visual>
      <origin rpy="0 0 0" xyz="0 0 0"/>
      <geometry>
        <box size="0.05 0.05 0.041"/>
      </geometry>
      <material name="DarkGrey"/>
    </visual>
    <collision>
      <origin rpy="0 0 0" xyz="0 0 0"/>
      <geometry>
        <box size="0.05 0.05 0.041"/>
      </geometry>
    </collision>
    <inertial>
      <inertia ixx="0.001" ixy="0" ixz="0" iyy="0.001" iyz="0" izz="0.001"/>
      <mass value="0.1"/>
    </inertial>
  </link>
  <link name="base_laser_middle">
    <visual>
      <origin rpy="0 0 0" xyz="0 0 0"/>
      <geometry>
        <cylinder length="0.0115" radius=".02"/>
      </geometry>
      <material name="dark_grey">
        <color rgba="0.2 0.2 0.2 1.0"/>
      </material>
    </visual>
    <collision>
      <origin rpy="0 0 0" xyz="0 0 0"/>
      <geometry>
        <cylinder length="0.0115" radius=".02"/>
      </geometry>
    </collision>
    <inertial>
      <inertia ixx="0.001" ixy="0" ixz="0" iyy="0.001" iyz="0" izz="0.001"/>
      <mass value="0.1"/>
    </inertial>
  </link>
  <joint name="base_laser_middle_joint" type="fixed">
    <parent link="base_laser_bottom"/>
    <child link="base_laser_middle"/>
    <origin rpy="0 0 0" xyz="0 0 0.02625"/>
  </joint>
  <link name="base_laser">
    <visual>
      <origin rpy="0 0 0" xyz="0 0 0"/>
      <geometry>
        <cylinder length="0.0175" radius=".0185"/>
      </geometry>
      <material name="red">
        <color rgba="0.8 0.1 0.1 1.0"/>
      </material>
    </visual>
    <collision>
      <origin rpy="0 0 0" xyz="0 0 0"/>
      <geometry>
        <cylinder length="0.0175" radius=".0185"/>
      </geometry>
    </collision>
    <inertial>
      <inertia ixx="0.001" ixy="0" ixz="0" iyy="0.001" iyz="0" izz="0.001"/>
      <mass value="0.1"/>
    </inertial>
  </link>
  <joint name="base_laser_joint" type="fixed">
    <parent link="base_laser_middle"/>
    <child link="base_laser"/>
    <origin rpy="0 0 0" xyz="0 0 0.0145"/>
  </joint>
</robot>

